<?xml version='1.0'?>
<robot xmlns:xacro="http://www.ros.org/wiki/xacro">

  <xacro:include filename="$(find rrmagnobot_simulation)/description/material.urdf.xacro"/>

  <link name="body_link">
  </link>

  <link name="body_footprint">
  </link>

  <joint name="body_footprint_joint" type="fixed">
      <parent link="body_link"/>
      <child link="body_footprint"/>
      <origin xyz="0 0 0" rpy="0 0 0"/>
  </joint>

  <joint name="base_body_joint" type="fixed">
      <parent link="body_link"/>
      <child link="base_link"/>
      <origin xyz="0 0 0" rpy="0 0 0"/>
  </joint>

  <link name="base_link">
    <inertial>
      <origin xyz="0.00096237 -0.01836 0.0013951" rpy="0 0 0" />
      <mass value="10.207" />
      <inertia
         ixx="0.5" ixy="0" ixz="0"
         iyy="1.0" iyz="0"
         izz="0.1" />
      </inertial>
    <visual>
      <origin xyz="0 0 0" rpy="0 0 0" />
      <geometry>
        <mesh filename="file://$(find rrmagnobot_simulation)/meshes/base_link.stl" />
      </geometry>
      <material name="white"/>
    </visual>
    <collision>
      <origin xyz="0 0 0" rpy="0 0 0" />
      <geometry>
        <mesh filename="file://$(find rrmagnobot_simulation)/meshes/base_link.stl" />
      </geometry>
    </collision>
  </link>

  <link name="left_motor_link">
    <inertial>
      <origin xyz="-6.9389E-18 -0.029509 1.3878E-17" rpy="0 0 0" />
      <mass value="1.483" />
      <inertia
        ixx="0.0078938" ixy="1.3747E-18" ixz="-2.0644E-19"
        iyy="0.014347" iyz="-3.4936E-18"
        izz="0.0078938" />
    </inertial>
    <visual>
      <origin xyz="0 0 0" rpy="0 0 0" />
      <geometry>
        <mesh filename="file://$(find rrmagnobot_simulation)/meshes/left_motor.stl" />
      </geometry>
      <material name="custom"/>
    </visual>
    <collision>
      <origin xyz="0 0 0" rpy="0 0 0" />
      <geometry>
        <mesh filename="file://$(find rrmagnobot_simulation)/meshes/left_motor.stl" />
      </geometry>
    </collision>
  </link>

  <link name="right_motor_link">
    <inertial>
      <origin xyz="0 -0.02951 7.5894E-18" rpy="0 0 0" />
      <mass value="1.483" />
      <inertia
        ixx="0.0078938" ixy="4.2444E-18" ixz="-7.123E-20"
        iyy="0.014347" iyz="-7.9282E-19"
        izz="0.0078938" />
    </inertial>
    <visual>
      <origin xyz="0 0 0" rpy="0 0 0" />
      <geometry>
        <mesh filename="file://$(find rrmagnobot_simulation)/meshes/right_motor.stl" />
      </geometry>
      <material name="custom"/>
    </visual>
    <collision>
      <origin xyz="0 0 0" rpy="0 0 0" />
      <geometry>
        <mesh filename="file://$(find rrmagnobot_simulation)/meshes/right_motor.stl" />
      </geometry>
    </collision>
  </link>

 <link name="tracker_link">
    <inertial>
      <origin xyz="0 -0.02951 7.5894E-18" rpy="0 0 0" />
      <mass value="1.483" />
      <inertia
        ixx="0.0078938" ixy="4.2444E-18" ixz="-7.123E-20"
        iyy="0.014347" iyz="-7.9282E-19"
        izz="0.0078938" />
    </inertial>
    <visual>
      <origin xyz="0 0 0" rpy="0 0 0" />
      <geometry>
        <mesh filename="file://$(find rrmagnobot_simulation)/meshes/Marker0.dae" />
      </geometry>
      <material name="custom"/>
    </visual>
    <collision>
      <origin xyz="0 0 0" rpy="0 0 0" />
      <geometry>
        <mesh filename="file://$(find rrmagnobot_simulation)/meshes/Marker0.dae" />
      </geometry>
    </collision>
  </link>

  <gazebo reference="base_link">
    <material>Gazebo/Orange</material>
  </gazebo>

  <gazebo reference="left_motor_link">
    <material>Gazebo/Blue</material>
  </gazebo>

  <gazebo reference="right_motor_link">
    <material>Gazebo/Blue</material>
  </gazebo>


  <joint name="left_motor_joint" type="continuous">
    <origin xyz="-0.31944 0.20433 -0.05511" rpy="-3.1415 3.1415 3.141" />
    <parent link="base_link" />
    <child link="left_motor_link" />
    <axis xyz="0 1 0" />
  </joint>

  <joint  name="right_motor_joint" type="continuous">
    <origin xyz="-0.3197 -0.23965 -0.05511" rpy="-3.14 3.1415 3.1395" />
    <parent link="base_link" />
    <child link="right_motor_link" />
    <axis xyz="0 1 0" />
  </joint>

  <joint name="tracker_joint" type="fixed">
    <origin xyz="0 0 0.3" rpy="0 1.57 0" />
    <parent link="base_link" />
    <child link="tracker_link" />
    <axis xyz="0 1 0" />
  </joint>

</robot>